<?xml version="1.0"?>
<robot name="Minotaur" xmlns:xacro="http://www.ros.org/wiki/xacro">

	<xacro:include filename="$(find ugv_bot)/ugvbot_description/ugvbot.gazebo" />
	
	<material name="blue">
		<color rgba="0 0 0.8 1"/>
	</material>
	<material name="black">
		<color rgba="0 0 0 1"/>
	</material>
	<material name="white">
		<color rgba="1 1 1 1"/>
	</material>
	
	<link name="base_link">
		<visual>
			<geometry>
				<box size="0.44 0.75 0.2"/>
			</geometry>
			<material name="blue"/>
		</visual>
		<collision>
			<geometry>
				<box size="0.44 0.75 0.2"/>
			</geometry>
		</collision>
		<inertial>
			<mass value="10.0"/>
			<origin xyz="0.0 0 0.1" rpy=" 0 0 0"/>
		         <inertia
			  ixx="0.5" ixy="0" ixz="0"
			  iyy="1.0" iyz="0"
			  izz="0.1"
		      />
		</inertial>
	</link>
	
	<link name="front_end">
		<visual>
			<geometry>
				<cylinder length="0.2" radius="0.22"/>
			</geometry>
			<material name="blue"/>
			<origin xyz="0 0 0"/>
		</visual>
		<collision>
			<geometry>
				<cylinder length="0.2" radius="0.22"/>
			</geometry>
		</collision>
		<inertial>
			<mass value="1.0"/>
			<origin xyz="0.0 0 0.1" rpy=" 0 0 0"/>
		         <inertia
			  ixx="0.5" ixy="0" ixz="0"
			  iyy="1.0" iyz="0"
			  izz="0.1"
		      />
		</inertial>
	</link>
	
	<joint name="front_base_joint" type="fixed">
		<parent link="base_link"/>
		<child link="front_end"/>
		<origin xyz="0 0.375 0"/>
	</joint>
	
	<link name="right_wheel">
		<visual>
			<origin rpy="0 1.5708 0" xyz="0 0 0"/>
			<geometry>
				<cylinder length="0.08" radius="0.16"/>
			</geometry>
			<material name="black"/>
		</visual>
		<collision>
			<origin rpy="0 1.5708 0" xyz="0 0 0"/>
			<geometry>
				<cylinder length="0.08" radius="0.16"/>
			</geometry>
			<contact_coefficients mu="1.0" kp="0.01" kd="0.01"/>
		</collision>
		<inertial>
			<mass value="5"/>
			<origin xyz="0.0 0 0.1" rpy=" 0 0 0"/>
		        <inertia
			ixx="1.0" ixy="0.0" ixz="0.0"
			iyy="1.0" iyz="0.0"
			izz="1.0"/>
		</inertial>
	</link>
		
	<joint name="right_wheel_joint" type="continuous">
		<parent link="front_end"/>
		<child link="right_wheel"/>
		<origin xyz="0.26 0.1 -0.09" rpy="1.5708 0 0"/>
	</joint>
	
	<link name="left_wheel">
		<visual>
			<origin rpy="0 1.5708 0" xyz="0 0 0"/>
			<geometry>
				<cylinder length="0.08" radius="0.16"/>
			</geometry>
			<material name="black"/>
		</visual>
		<collision>
			<origin rpy="0 1.5708 0" xyz="0 0 0"/>
			<geometry>
				<cylinder length="0.08" radius="0.16"/>
			</geometry>
		</collision>
		<inertial>
			<mass value="5"/>
			<origin xyz="0.0 0 0.1" rpy=" 0 0 0"/>
		     	<inertia
			ixx="1.0" ixy="0.0" ixz="0.0"
			iyy="1.0" iyz="0.0"
			izz="1.0"/>
		</inertial>
	</link>
		
	<joint name="left_wheel_joint" type="continuous">
		<parent link="front_end"/>
		<child link="left_wheel"/>
		<origin xyz="-0.26 0.1 -0.09" rpy="1.5708 0 0"/>
	</joint>
	
	<link name="right_mast">
		<visual>
			<geometry>
				<box size="0.05 0.05 0.74"/>
			</geometry>
			<material name="white"/>
		</visual>
		<collision>
			<geometry>
				<box size="0.05 0.05 0.74"/>
			</geometry>
		</collision>
		<inertial>
			<mass value="1"/>
			<origin xyz="0.0 0 0.1" rpy=" 0 0 0"/>
		        <inertia
			  ixx="0.5" ixy="0" ixz="0"
			  iyy="1.0" iyz="0"
			  izz="0.1"
		      />
		</inertial>
	</link>
	
	<link name="left_mast">
		<visual>
			<geometry>
				<box size="0.05 0.05 0.74"/>
			</geometry>
			<material name="white"/>
		</visual>
		<collision>
			<geometry>
				<box size="0.05 0.05 0.74"/>
			</geometry>
		</collision>
		<inertial>
			<mass value="1"/>
			<origin xyz="0.0 0 0.1" rpy=" 0 0 0"/>
		        <inertia
			  ixx="0.5" ixy="0" ixz="0"
			  iyy="1.0" iyz="0"
			  izz="0.1"
		      />
		</inertial>
	</link>
	
	<joint name="right_mast_joint" type="fixed">
		<parent link="base_link"/>
		<child link="right_mast"/>
		<origin xyz="0.195 0.1 0.47"/>
	</joint>
	
	<joint name="left_mast_joint" type="fixed">
		<parent link="base_link"/>
		<child link="left_mast"/>
		<origin xyz="-0.195 0.1 0.47"/>
	</joint>	
	
	<link name="mast_link">
		<visual>
			<geometry>
				<box size="0.34 0.05 0.05"/>
				<origin xyz="0 0 0"/>
			</geometry>
			<material name="white"/>
		</visual>
		<collision>
			<geometry>
				<box size="0.34 0.05 0.05"/>
			</geometry>
		</collision>
		<inertial>
			<mass value="0.1"/>
			<origin xyz="0.0 0 0.1" rpy=" 0 0 0"/>
		        <inertia
			  ixx="1" ixy="0" ixz="0"
			  iyy="1" iyz="0"
			  izz="1"
		      />
		</inertial>
	</link>

	
	
	<joint name="left_cam_joint" type="fixed">
		<parent link="left_mast"/>
		<child link="mast_link"/>
		<origin xyz="0.195 0 0.25"/>
	</joint>

  <link name="camera">
    <visual>
      <origin xyz="0 0 0" rpy="0 0 0"/>
      <geometry>
        <box size="0.07 0.07 0.07"/>
      </geometry>
      <material name="black"/>
    </visual>
    <collision>
      <geometry>
        <box size="0.07 0.07 0.07"/>
      </geometry>
    </collision>
    <inertial>
      <mass value="0.2"/>
      <box_inertia m="0.2" x="0.07" y="0.07" z="0.07" />
      <inertia ixx="1e-6" ixy="0" ixz="0" iyy="1e-6" iyz="0" izz="1e-6" />
    </inertial>
  </link>

  <joint name="cam_joint" type="fixed">
    <axis xyz="1 0 0" />
    <parent link="mast_link"/>
    <child link="camera"/>
    <origin xyz="0 0 0" rpy="0 0 1.5708"/>
  </joint>

	<link name="hokuyo">
    <collision>
      <origin xyz="0 0 0" rpy="0 1.5708 0"/>
      <geometry>
    <box size="0.1 0.1 0.1"/>
      </geometry>
    </collision>

    <visual>
      <origin xyz="0 0 0" rpy="0 0 0"/>
      <geometry>
        <mesh filename="package://ugv_bot/ugvbot_description/hokuyo.dae"/>
      </geometry>
    </visual>

    <inertial>
      <mass value="1e-5" />
      <origin xyz="0 0 0" rpy="0 0 0"/>
      <inertia ixx="1e-6" ixy="0" ixz="0" iyy="1e-6" iyz="0" izz="1e-6" />
    </inertial>
  </link>

 <joint name="hokuyo_joint" type="fixed">
    <axis xyz="0 0 1" />
    <origin xyz="0 0 0.15" rpy="0 0 1.5708"/>
    <parent link="front_end"/>
    <child link="hokuyo"/>
  </joint>
		
	<!--joint name="right_cam_joint" type="fixed">
		<parent link="right_mast"/>
		<child link="mast_link"/>
		<origin xyz="-0.195 0 0.25"/>
	</joint -->
	
	<link name="caster_wheel">
		<visual>
			<origin rpy="0 1.5708 0" xyz="0 0 0"/>
			<geometry>
				<cylinder length="0.1" radius="0.075"/>
			</geometry>
			<material name="white"/>
		</visual>
		<collision>
			<origin rpy="0 1.5708 0" xyz="0 0 0"/>
			<geometry>
				<cylinder length="0.1" radius="0.075"/>
			</geometry>
		</collision>
		<inertial>
			<mass value="1"/>
			<origin xyz="0.0 0 0.1" rpy=" 0 0 0"/>
		        <inertia
			ixx="0.01" ixy="0.0" ixz="0.0"
			iyy="0.01" iyz="0.0"
			izz="0.01"/>
		</inertial>
	</link>
	
	<joint name="caster_joint" type="continuous">
		<parent link="base_link"/>
		<child link="caster_wheel"/>
		<origin xyz="0 -0.35 -0.175" rpy="1.5708 0 0"/>
	</joint>
</robot>
